Workbook

Sheet Dashboard
C2: AUSTIN ENERGY COMBINED CONTACT CENTER CUSTOMER SATISFACTION
C6: REPORTING PERIOD | E6: Q2_2025
C8: UTILITY CALLING ABOUT | F8: IVR RATINGS | H8: PERCEPTIONS OF CSR | M8: OVERALL SATISFACTION RATING
C20: % Placed on Hold | E20: Time on Hold | J20: Comments from dissatisfied customer callbacks
C21: {=IFERROR(_xlfn._xlws.FILTER('[1]Customers Data'!C4:C1000,TEXT('[1]Customers Data'!B4:B1000,"MMMM")=E6),"")} | D21: {=IFERROR(_xlfn._xlws.FILTER('[1]Customers Data'!H4:H1000,TEXT('[1]Customers Data'!B4:B1000,"MMMM")=E6),"")} | E21: Less than 2 minutes | F21: Between 2 and 5 minutes

Sheet Customers Data
B3: Date | C3: Customer Name | D3: Email | E3: Purchase ID | F3: Product Satisfaction | G3: Delivery Satisfaction | H3: Overall Experience | I3: Avg Time to Solve An Issue | J3: Customer Satisfaction | K3: Customer Comments:
B4: 44927 | C4: John Smith | D4: john.smith@email.com | E4: WIAS123 | F4: 4.5 | G4: 4.7 | H4: 4.6 | I4: Less than 1 hour | J4: Neutral | K4: John Smith: "Great product quality! Fast delivery."
B5: 44928 | C5: Sarah Johnson | D5: sarah@email.com | E5: WIAS124 | F5: 4.8 | G5: 4.5 | H5: 4.65 | I5: 1-2 hours | J5: Neutral | K5: Sarah Johnson: "Love the variety. Could improve delivery tracking."
B6: 44929 | C6: Michael Davis | D6: michael@email.com | E6: WIAS125 | F6: 4.2 | G6: 4.6 | H6: 4.4 | I6: More than 2 hours | J6: Very Unsatisfied | K6: Michael Davis: "Satisfied overall, but sizing was a bit off."
B7: 44930 | C7: Emily White | D7: emily@email.com | E7: WIAS126 | F7: 4.9 | G7: 4.8 | H7: 4.85 | I7: 1-2 hours | J7: Unsatisfied | K7: Emily White: "Excellent service! Will shop again."
B8: 44959 | C8: Brian Thompson | D8: brian@email.com | E8: WIAS127 | F8: 4.7 | G8: 4.4 | H8: 4.55 | I8: Less than 1 hour | J8: Very Satisfied | K8: Brian Thompson: "Good prices, but product descriptions could be clearer."
B9: 44960 | C9: Jessica Turner | D9: jessica@email.com | E9: WIAS128 | F9: 4.6 | G9: 4.5 | H9: 4.55 | I9: Less than 1 hour | J9: Very Satisfied | K9: Jessica Turner: "Comfortable clothing. Delivery was on time."
B10: 44961 | C10: Kevin Miller | D10: kevin@email.com | E10: WIAS129 | F10: 4.3 | G10: 4.2 | H10: 4.25 | I10: Less than 1 hour | J10: Very Satisfied | K10: Kevin Miller: "Decent experience, but packaging could be more eco-friendly."
B11: 44962 | C11: Lauren Adams | D11: lauren@email.com | E11: WIAS130 | F11: 4.8 | G11: 4.7 | H11: 4.75 | I11: Less than 1 hour | J11: Satisfied | K11: Lauren Adams: "Highly satisfied. Good job on the new collection."
B12: 44963 | C12: Ryan Cooper | D12: ryan@email.com | E12: WIAS131 | F12: 4.5 | G12: 4.6 | H12: 4.55 | I12: Less than 1 hour | J12: Satisfied | K12: Ryan Cooper: "Quality products, but website navigation needs improvement."
B13: 44964 | C13: Ashley Parker | D13: ashley@email.com | E13: WIAS132 | F13: 4.7 | G13: 4.9 | H13: 4.8 | I13: 1-2 hours | J13: Neutral | K13: Ashley Parker: "Amazing experience. Will recommend to friends."

Sheet Chart Data
H1: {=INDEX('Chart Data'!$H$5:$L$10, ROWS('Chart Data'!$H$5:H5), MATCH($E$6, 'Chart Data'!I4:L4, 0))} -> #N/A
A3: Utility Calling About | H3: IVR Ratings | Q3: Perception of CSR
B4: Series 1 | C4: 5 | I4: Q4_2024 | J4: Q1_2025 | K4: Q2_2025 | L4: Q3_2025 | N4: Metric | O4: Selected_Period | R4: Q3_2024 | S4: Q4_2024 | T4: Q1_2025 | U4: Q2_2025 | V4: Q3_2025
A5: Electricity | B5: 0.57281553 | C5: 4 | H5: Reasonableness of hold time* | I5: 0.70238095 | J5: 0.62068966 | K5: 0.63636364 | L5: 0.48275862 | N5: =H5 -> Reasonableness of hold time* | O5: {=--INDEX($I$5:$L$10, ROWS($H$5:H5), MATCH(Dashboard!$E$6, $I$4:$L$4, 0))} -> 0.63636364 | Q5: Spoke Clearly/Easy to Understand | R5: 0.93532338 | S5: 0.9009901 | T5: 0.92380952 | U5: 0.94059406 | V5: 0.81372549
A6: Water | B6: 0.13592233 | C6: 3 | H6: Overall communication | I6: 0.59512195 | J6: 0.58095238 | K6: 0.69607843 | L6: 0.53398058 | N6: =H6 -> Overall communication | O6: {=--INDEX($I$5:$L$10, ROWS($H$5:H6), MATCH(Dashboard!$E$6, $I$4:$L$4, 0))} -> 0.69607843 | Q6: Courteous | R6: 0.93532338 | S6: 0.9009901 | T6: 0.9047619 | U6: 0.93069307 | V6: 0.78431373
A7: Solid Waste | B7: 0.087378641 | C7: 2 | H7: Easy to use | I7: 0.66829268 | J7: 0.64761905 | K7: 0.75490196 | L7: 0.54368932 | N7: =H7 -> Easy to use | O7: {=--INDEX($I$5:$L$10, ROWS($H$5:H7), MATCH(Dashboard!$E$6, $I$4:$L$4, 0))} -> 0.75490196 | Q7: Eagerness to Help You | R7: 0.91044776 | S7: 0.89108911 | T7: 0.81904762 | U7: 0.87128713 | V7: 0.69607843
A8: Don't know/no answer | B8: 0.0097087379 | C8: 1 | H8: Provided necessary information | I8: 0.62439024 | J8: 0.59047619 | K8: 0.69607843 | L8: 0.57281553 | N8: =H8 -> Provided necessary information | O8: {=--INDEX($I$5:$L$10, ROWS($H$5:H8), MATCH(Dashboard!$E$6, $I$4:$L$4, 0))} -> 0.69607843 | Q8: Acknowledged Issue or Concern | R8: 0.92537313 | S8: 0.88613861 | T8: 0.86666667 | U8: 0.87128713 | V8: 0.68627451
A9: Other | B9: 0.19417476 | H9: Appropriateness of wait time* | I9: 0.65365854 | J9: 0.6 | K9: 0.75490196 | L9: 0.58252427 | N9: =H9 -> Appropriateness of wait time* | O9: {=--INDEX($I$5:$L$10, ROWS($H$5:H9), MATCH(Dashboard!$E$6, $I$4:$L$4, 0))} -> 0.75490196 | Q9: Ensured Understanding of Issue or Process | R9: 0.87562189 | S9: 0.86633663 | T9: 0.83809524 | U9: 0.87128713 | V9: 0.68627451
H10: Usefulness of wait time message | I10: 0.76068376 | J10: 0.69491525 | K10: 0.875 | L10: 0.5915493 | N10: =H10 -> Usefulness of wait time message | O10: {=--INDEX($I$5:$L$10, ROWS($H$5:H10), MATCH(Dashboard!$E$6, $I$4:$L$4, 0))} -> 0.875 | Q10: Valued as a Customer | R10: 0.87064677 | S10: 0.86138614 | T10: 0.84761905 | U10: 0.88118812 | V10: 0.64705882
Q11: Satisfied with Call Outcome | R11: 0.86 | S11: 0.85 | T11: 0.82 | U11: 0.86 | V11: 0.59
Q12: Offered Appropriate Program and Plans | R12: 0.64 | S12: 0.68 | T12: 0.65 | U12: 0.72 | V12: 0.57
H14: =Dashboard!$E$6 -> Q2_2025
H15: =MATCH(Dashboard!$E$6, $I$4:$L$4, 0) -> 3
A21: Overall Satisfaction
B22: Satisfied with Call Outcome | I22: Q3_2024 | J22: Q4_2024 | K22: Q1_2025 | L22: Q2_2025 | M22: Q3_2025
A23: Q3_2024 | B23: 0.8592233 | H23: Satisfied with Call Outcome | I23: 0.8592233 | J23: 0.84878049 | K23: 0.81904762 | L23: 0.8627451 | M23: 0.59223301
A24: Q4_2024 | B24: 0.84878049
A25: Q1_2025 | B25: 0.81904762
A26: Q2_2025 | B26: 0.8627451
A27: Q3_2025 | B27: 0.59223301

Sheet Sheet1
A1: sys_RespNum | B1: S1 | C1: SR2 | D1: SR3 | E1: SC4 | F1: S5 | G1: Type | H1: Q1 | I1: Q1_4_other | J1: Q2 | K1: Q3 | L1: Q3_12_other | M1: Q3_15_other | N1: Q3_24_other | O1: Q4 | P1: Q4#_1 | Q1: Q4#_2 | R1: Q4#_3 | S1: Q5 | T1: Q6_r1 | U1: Q6_r2 | V1: Q6_r3 | W1: Q6_r4 | X1: Q7Low_r1_c1 | Y1: Q7r1_Low#1 | Z1: Q7r1_Low#2 | AA1: Q7r1_Low#3 | AB1: Q7r1_Low#4 | AC1: Q7High_r1_c1 | AD1: Q7r1_High#1 | AE1: Q7r1_High#2 | AF1: Q7r1_High#3 | AG1: Q7r1_High#4 | AH1: Q7Low_r2_c1 | AI1: Q7r2_Low#1 | AJ1: Q7r2_Low#2 | AK1: Q7r2_Low#3 | AL1: Q7r2_Low#4 | AM1: Q7High_r2_c1 | AN1: Q7r2_High#1 | AO1: Q7r2_High#2 | AP1: Q7r2_High#3 | AQ1: Q7r2_High#4 | AR1: Q7Low_r3_c1 | AS1: Q7r3_Low#1 | AT1: Q7r3_Low#2 | AU1: Q7r3_Low#3 | AV1: Q7r3_Low#4 | AW1: Q7High_r3_c1 | AX1: Q7r3_High#1 | AY1: Q7r3_High#2 | AZ1: Q7r3_High#3 | BA1: Q7r3_High#4 | BB1: Q7Low_r4_c1 | BC1: Q7r4_Low#1 | BD1: Q7r4_Low#2 | BE1: Q7r4_Low#3 | BF1: Q7r4_Low#4 | BG1: Q7High_r4_c1 | BH1: Q7r4_High#1 | BI1: Q7r4_High#2 | BJ1: Q7r4_High#3 | BK1: Q7r4_High#4 | BL1: Q8 | BM1: Q9 | BN1: Q10 | BO1: Q10_1 | BP1: Q10_2 | BQ1: Q10_3 | BR1: Q10_4 | BS1: Q11 | BT1: Q12 | BU1: Q12_1 | BV1: Q12_2 | BW1: Q12_3 | BX1: Q12A | BY1: Q12B | BZ1: Q12B_1 | CA1: Q12B_2 | CB1: Q12B_3 | CC1: Q13 | CD1: Q14 | CE1: Q15 | CF1: Q16 | CG1: Q17 | CH1: Q18 | CI1: Q18_1 | CJ1: Q18_2 | CK1: Q18_3 | CL1: Q19 | CM1: Q20 | CN1: Q20_1 | CO1: Q20_2 | CP1: Q20_3 | CQ1: Q21 | CR1: Q22 | CS1: Q23_r1 | CT1: Q23_r2 | CU1: Q23_r3 | CV1: Q23_r4 | CW1: Q23_r5 | CX1: Q23_r6 | CY1: Q23_r7 | CZ1: Q24 | DA1: Q24_1 | DB1: Q24_2 | DC1: Q25 | DD1: Q26_1 | DE1: Q26_2 | DF1: Q26_3 | DG1: Q26_4 | DH1: Q26_5 | DI1: Q26_6 | DJ1: Q26_7 | DK1: Q26_8 | DL1: Q26_9 | DM1: Q26_9_other | DN1: Q27 | DO1: Q28 | DP1: Q28_1 | DQ1: Q28_2 | DR1: Q29 | DS1: Q30 | DT1: Q30_1 | DU1: Q30_2 | DV1: Q30_3 | DW1: Q31 | DX1: Q32 | DY1: Q33 | DZ1: Q33_1 | EA1: DC1 | EB1: DC1_3_other | EC1: DC1_5_other | ED1: DC1_9_other | EE1: DC1_19_other | EF1: DC1_20_other | EG1: DC1_21_other | EH1: DC1_22_other | EI1: DC2 | EJ1: DC3 | EK1: DC4 | EL1: DC5 | EM1: DR1 | EN1: DR2 | EO1: DR2_6_other | EP1: DR3 | EQ1: DR4 | ER1: DR5 | ES1: DR6 | ET1: DR7 | EU1: DR8 | EV1: DR9 | EW1: DR10 | EX1: DR11 | EY1: ContactInfo_first | EZ1: ContactInfo_last | FA1: ContactInfo_Company | FB1: ContactInfo_email | FC1: ContactInfo_Phone | FD1: InterID | FE1: Month | FF1: QtaMonth | FG1: Date | FH1: sys_EndTime | FI1: ID
A2: 17 | B2: 1 | C2: 2 | D2: 1 | E2: #NULL! | F2: 2 | G2: 2 | H2: 4 | I2: Payment | J2: 1 | K2: 11 | P2: #NULL! | Q2: #NULL! | R2: #NULL! | S2: #NULL! | T2: 5 | U2: 5 | V2: 7 | W2: 8 | Y2: #NULL! | Z2: #NULL! | AA2: #NULL! | AB2: #NULL! | AD2: #NULL! | AE2: #NULL! | AF2: #NULL! | AG2: #NULL! | AI2: #NULL! | AJ2: #NULL! | AK2: #NULL! | AL2: #NULL! | AN2: #NULL! | AO2: #NULL! | AP2: #NULL! | AQ2: #NULL! | AS2: #NULL! | AT2: #NULL! | AU2: #NULL! | AV2: #NULL! | AX2: #NULL! | AY2: #NULL! | AZ2: #NULL! | BA2: #NULL! | BC2: #NULL! | BD2: #NULL! | BE2: #NULL! | BF2: #NULL! | BG2: It was short enough | BH2: 21 | BI2: #NULL! | BJ2: #NULL! | BK2: #NULL! | BL2: 2 | BM2: 4 | BN2: I don't remember. Probably something about being able to do the things I wanted to do online; which I couldn't, because I would have been doing them online if I could. | BO2: 1 | BP2: #NULL! | BQ2: #NULL! | BR2: #NULL! | BS2: 7 | BT2: Letting people who have trouble paying know that there are options and that they should ask about those options. | BU2: 1 | BV2: #NULL! | BW2: #NULL! | BX2: #NULL! | BZ2: #NULL! | CA2: #NULL! | CB2: #NULL! | CC2: 3 | CD2: #NULL! | CE2: 1 | CF2: 1 | CG2: 1 | CH2: Different section of the center. | CI2: 1 | CJ2: #NULL! | CK2: #NULL! | CL2: 8 | CN2: #NULL! | CO2: #NULL! | CP2: #NULL! | CQ2: 1 | CR2: 8 | CS2: 10 | CT2: 10 | CU2: 10 | CV2: 10 | CW2: 10 | CX2: 10 | CY2: 10 | DA2: #NULL! | DB2: #NULL! | DC2: 9 | DD2: #NULL! | DE2: #NULL! | DF2: #NULL! | DG2: #NULL! | DH2: #NULL! | DI2: #NULL! | DJ2: #NULL! | DK2: #NULL! | DL2: #NULL! | DN2: 1 | DP2: #NULL! | DQ2: #NULL! | DR2: #NULL! | DT2: #NULL! | DU2: #NULL! | DV2: #NULL! | DW2: 2 | DX2: 2 | DZ2: #NULL! | EA2: #NULL! | EI2: #NULL! | EJ2: #NULL! | EK2: #NULL! | EL2: #NULL! | EM2: 9 | EN2: 6 | EO2: Mutt | EP2: 5 | EQ2: 1 | ER2: 2 | ES2: 78723 | ET2: 4 | EU2: 3 | EV2: 2 | EW2: 5 | EX2: 3 | EY2: RAnthony | EZ2: Steele | FB2: ranthonysteele@gmail.com | FC2: 5129260317 | FD2: 0 | FE2: #NULL! | FF2: 2 | FH2: 22 Jul 2025 - 14:42:03 CDT | FI2: 1109
A3: 18 | B3: 1 | C3: 2 | D3: 1 | E3: #NULL! | F3: 2 | G3: 2 | H3: 2 | J3: 1 | K3: 9 | P3: #NULL! | Q3: #NULL! | R3: #NULL! | S3: #NULL! | T3: 11 | U3: 11 | V3: 8 | W3: 11 | Y3: #NULL! | Z3: #NULL! | AA3: #NULL! | AB3: #NULL! | AD3: #NULL! | AE3: #NULL! | AF3: #NULL! | AG3: #NULL! | AI3: #NULL! | AJ3: #NULL! | AK3: #NULL! | AL3: #NULL! | AN3: #NULL! | AO3: #NULL! | AP3: #NULL! | AQ3: #NULL! | AS3: #NULL! | AT3: #NULL! | AU3: #NULL! | AV3: #NULL! | AW3: 10 | AX3: #NULL! | AY3: #NULL! | AZ3: #NULL! | BA3: #NULL! | BC3: #NULL! | BD3: #NULL! | BE3: #NULL! | BF3: #NULL! | BH3: #NULL! | BI3: #NULL! | BJ3: #NULL! | BK3: #NULL! | BL3: 2 | BM3: 5 | BN3: No remember | BO3: 98 | BP3: #NULL! | BQ3: #NULL! | BR3: #NULL! | BS3: 11 | BT3: No remember | BU3: 98 | BV3: #NULL! | BW3: #NULL! | BX3: #NULL! | BZ3: #NULL! | CA3: #NULL! | CB3: #NULL! | CC3: 1 | CD3: 9 | CE3: 2 | CF3: #NULL! | CG3: #NULL! | CI3: #NULL! | CJ3: #NULL! | CK3: #NULL! | CL3: #NULL! | CN3: #NULL! | CO3: #NULL! | CP3: #NULL! | CQ3: 2 | CR3: #NULL! | CS3: 10 | CT3: 10 | CU3: 10 | CV3: 10 | CW3: 10 | CX3: 10 | CY3: 10 | DA3: #NULL! | DB3: #NULL! | DC3: 10 | DD3: #NULL! | DE3: #NULL! | DF3: #NULL! | DG3: #NULL! | DH3: #NULL! | DI3: #NULL! | DJ3: #NULL! | DK3: #NULL! | DL3: #NULL! | DN3: 3 | DO3: Service was great he helps me 100% | DP3: 97 | DQ3: #NULL! | DR3: #NULL! | DT3: #NULL! | DU3: #NULL! | DV3: #NULL! | DW3: 3 | DX3: 2 | DZ3: #NULL! | EA3: #NULL! | EI3: #NULL! | EJ3: #NULL! | EK3: #NULL! | EL3: #NULL! | EM3: 6 | EN3: 6 | EO3: Puertorican | EP3: 6 | EQ3: 2 | ER3: 1 | ES3: 78704 | ET3: 5 | EU3: 6 | EV3: 1 | EW3: 5 | EX3: 2 | EY3: Vivian | EZ3: Hernandez | FB3: Hvivian88@gmail.com | FC3: 5126196064 | FD3: 0 | FE3: #NULL! | FF3: 2 | FH3: 22 Jul 2025 - 14:50:06 CDT | FI3: 860
A4: 25 | B4: 1 | C4: 2 | D4: 1 | E4: #NULL! | F4: 2 | G4: 2 | H4: 3 | J4: 1 | K4: 2 | P4: #NULL! | Q4: #NULL! | R4: #NULL! | S4: #NULL! | T4: 8 | U4: 8 | V4: 9 | W4: 9 | Y4: #NULL! | Z4: #NULL! | AA4: #NULL! | AB4: #NULL! | AC4: N/a | AD4: 97 | AE4: #NULL! | AF4: #NULL! | AG4: #NULL! | AI4: #NULL! | AJ4: #NULL! | AK4: #NULL! | AL4: #NULL! | AM4: N/a | AN4: 97 | AO4: #NULL! | AP4: #NULL! | AQ4: #NULL! | AS4: #NULL! | AT4: #NULL! | AU4: #NULL! | AV4: #NULL! | AW4: Blind, use phone | AX4: 99 | AY4: #NULL! | AZ4: #NULL! | BA4: #NULL! | BC4: #NULL! | BD4: #NULL! | BE4: #NULL! | BF4: #NULL! | BG4: N/a | BH4: 97 | BI4: #NULL! | BJ4: #NULL! | BK4: #NULL! | BL4: 2 | BM4: 4 | BN4: ??????????? | BO4: 99 | BP4: #NULL! | BQ4: #NULL! | BR4: #NULL! | BS4: 8 | BT4: Time to reach rep | BU4: 6 | BV4: #NULL! | BW4: #NULL! | BX4: #NULL! | BZ4: #NULL! | CA4: #NULL! | CB4: #NULL! | CC4: 2 | CD4: #NULL! | CE4: 1 | CF4: 1 | CG4: 2 | CH4: Have a modest in ground pool for medical/ physical therapy. During the wastewater measuring period, the pool water used for each filling is about 600 gallons/ it needs filling about every 6 weeks this water use adds to my monthly water bill for the year. A small amount of water is used every other month to backwash the filter. It is drained for repairs every 1o years. It is not fair | CI4: 2 | CJ4: #NULL! | CK4: #NULL! | CL4: 5 | CM4: Do not include pool filling in my annual/monthly water bill. | CN4: 99 | CO4: #NULL! | CP4: #NULL! | CQ4: 3 | CR4: #NULL! | CS4: 10 | CT4: 6 | CU4: 5 | CV4: 5 | CW4: 6 | CX4: 8 | CY4: 9 | CZ4: Help instead of just saying no | DA4: 5 | DB4: #NULL! | DC4: 3 | DD4: 0 | DE4: 0 | DF4: 0 | DG4: 0 | DH4: 0 | DI4: 1 | DJ4: 0 | DK4: 0 | DL4: 0 | DN4: 2 | DO4: ????? | DP4: 99 | DQ4: #NULL! | DR4: #NULL! | DT4: #NULL! | DU4: #NULL! | DV4: #NULL! | DW4: 1 | DX4: 2 | DZ4: #NULL! | EA4: #NULL! | EI4: #NULL! | EJ4: #NULL! | EK4: #NULL! | EL4: #NULL! | EM4: 10 | EN4: 1 | EP4: 5 | EQ4: 1 | ER4: 2 | ES4: 78759 | ET4: 2 | EU4: 4 | EV4: 8 | EW4: 5 | EX4: 1 | EY4: GERALD | EZ4: OROURKE | FB4: GOROURKE@AUSTIN.RR.COM | FC4: 5129920125 | FD4: 10098 | FE4: #NULL! | FF4: 2 | FH4: 29 Jul 2025 - 11:06:51 CDT | FI4: 836
A5: 28 | B5: 1 | C5: 2 | D5: 1 | E5: #NULL! | F5: 2 | G5: 2 | H5: 2 | J5: 1 | K5: 2 | P5: #NULL! | Q5: #NULL! | R5: #NULL! | S5: #NULL! | T5: 8 | U5: 8 | V5: 8 | W5: 7 | Y5: #NULL! | Z5: #NULL! | AA5: #NULL! | AB5: #NULL! | AC5: 8 | AD5: #NULL! | AE5: #NULL! | AF5: #NULL! | AG5: #NULL! | AI5: #NULL! | AJ5: #NULL! | AK5: #NULL! | AL5: #NULL! | AM5: 8 | AN5: #NULL! | AO5: #NULL! | AP5: #NULL! | AQ5: #NULL! | AS5: #NULL! | AT5: #NULL! | AU5: #NULL! | AV5: #NULL! | AW5: 8 | AX5: #NULL! | AY5: #NULL! | AZ5: #NULL! | BA5: #NULL! | BC5: #NULL! | BD5: #NULL! | BE5: #NULL! | BF5: #NULL! | BH5: #NULL! | BI5: #NULL! | BJ5: #NULL! | BK5: #NULL! | BL5: 1 | BM5: #NULL! | BO5: #NULL! | BP5: #NULL! | BQ5: #NULL! | BR5: #NULL! | BS5: #NULL! | BU5: #NULL! | BV5: #NULL! | BW5: #NULL! | BX5: #NULL! | BZ5: #NULL! | CA5: #NULL! | CB5: #NULL! | CC5: 2 | CD5: #NULL! | CE5: 2 | CF5: #NULL! | CG5: #NULL! | CI5: #NULL! | CJ5: #NULL! | CK5: #NULL! | CL5: #NULL! | CN5: #NULL! | CO5: #NULL! | CP5: #NULL! | CQ5: 2 | CR5: #NULL! | CS5: 9 | CT5: 9 | CU5: 9 | CV5: 9 | CW5: 9 | CX5: 9 | CY5: 9 | DA5: #NULL! | DB5: #NULL! | DC5: 9 | DD5: #NULL! | DE5: #NULL! | DF5: #NULL! | DG5: #NULL! | DH5: #NULL! | DI5: #NULL! | DJ5: #NULL! | DK5: #NULL! | DL5: #NULL! | DN5: 1 | DP5: #NULL! | DQ5: #NULL! | DR5: #NULL! | DT5: #NULL! | DU5: #NULL! | DV5: #NULL! | DW5: 3 | DX5: 2 | DZ5: #NULL! | EA5: #NULL! | EI5: #NULL! | EJ5: #NULL! | EK5: #NULL! | EL5: #NULL! | EM5: 10 | EN5: 1 | EP5: 5 | EQ5: 1 | ER5: 2 | ES5: 78746 | ET5: 2 | EU5: 4 | EV5: 5 | EW5: 5 | EX5: 1 | EY5: Ron | EZ5: Pauley | FB5: Rapauley47@austin.rr.com | FC5: 513-423-6030 | FD5: #NULL! | FE5: #NULL! | FF5: 3 | FH5: 11 Aug 2025 - 15:38:32 CDT | FI5: 12536
A6: 29 | B6: 1 | C6: 2 | D6: 1 | E6: #NULL! | F6: 2 | G6: 2 | H6: 2 | J6: 1 | K6: 15 | M6: Balance | P6: #NULL! | Q6: #NULL! | R6: #NULL! | S6: #NULL! | T6: 10 | U6: 10 | V6: 10 | W6: 10 | Y6: #NULL! | Z6: #NULL! | AA6: #NULL! | AB6: #NULL! | AC6: 10 | AD6: #NULL! | AE6: #NULL! | AF6: #NULL! | AG6: #NULL! | AI6: #NULL! | AJ6: #NULL! | AK6: #NULL! | AL6: #NULL! | AM6: 10 | AN6: #NULL! | AO6: #NULL! | AP6: #NULL! | AQ6: #NULL! | AS6: #NULL! | AT6: #NULL! | AU6: #NULL! | AV6: #NULL! | AW6: 10 | AX6: #NULL! | AY6: #NULL! | AZ6: #NULL! | BA6: #NULL! | BC6: #NULL! | BD6: #NULL! | BE6: #NULL! | BF6: #NULL! | BG6: 10 | BH6: #NULL! | BI6: #NULL! | BJ6: #NULL! | BK6: #NULL! | BL6: 1 | BM6: #NULL! | BO6: #NULL! | BP6: #NULL! | BQ6: #NULL! | BR6: #NULL! | BS6: #NULL! | BU6: #NULL! | BV6: #NULL! | BW6: #NULL! | BX6: #NULL! | BZ6: #NULL! | CA6: #NULL! | CB6: #NULL! | CC6: 2 | CD6: #NULL! | CE6: 2 | CF6: #NULL! | CG6: #NULL! | CI6: #NULL! | CJ6: #NULL! | CK6: #NULL! | CL6: #NULL! | CN6: #NULL! | CO6: #NULL! | CP6: #NULL! | CQ6: 2 | CR6: #NULL! | CS6: 10 | CT6: 10 | CU6: 10 | CV6: 10 | CW6: 10 | CX6: 10 | CY6: 10 | DA6: #NULL! | DB6: #NULL! | DC6: 10 | DD6: #NULL! | DE6: #NULL! | DF6: #NULL! | DG6: #NULL! | DH6: #NULL! | DI6: #NULL! | DJ6: #NULL! | DK6: #NULL! | DL6: #NULL! | DN6: 1 | DP6: #NULL! | DQ6: #NULL! | DR6: #NULL! | DT6: #NULL! | DU6: #NULL! | DV6: #NULL! | DW6: 2 | DX6: 1 | DY6: Weatherzarion | DZ6: 99 | EA6: #NULL! | EI6: #NULL! | EJ6: #NULL! | EK6: #NULL! | EL6: #NULL! | EM6: 10 | EN6: 6 | EO6: White | EP6: 5 | EQ6: 1 | ER6: 2 | ES6: 78744 | ET6: 3 | EU6: 4 | EV6: 6 | EW6: 5 | EX6: 1 | EY6: Allan | EZ6: Mexas | FB6: Ahmexas@gmail.coñm | FC6: 5134175794 | FD6: #NULL! | FE6: #NULL! | FF6: 2 | FH6: 11 Aug 2025 - 16:03:53 CDT | FI6: 3122
A7: 31 | B7: 1 | C7: 2 | D7: 1 | E7: #NULL! | F7: 2 | G7: 2 | H7: 2 | J7: 1 | K7: 3 | P7: #NULL! | Q7: #NULL! | R7: #NULL! | S7: #NULL! | T7: 10 | U7: 10 | V7: 10 | W7: 10 | Y7: #NULL! | Z7: #NULL! | AA7: #NULL! | AB7: #NULL! | AC7: 10 | AD7: #NULL! | AE7: #NULL! | AF7: #NULL! | AG7: #NULL! | AI7: #NULL! | AJ7: #NULL! | AK7: #NULL! | AL7: #NULL! | AM7: 10 | AN7: #NULL! | AO7: #NULL! | AP7: #NULL! | AQ7: #NULL! | AS7: #NULL! | AT7: #NULL! | AU7: #NULL! | AV7: #NULL! | AW7: 10 | AX7: #NULL! | AY7: #NULL! | AZ7: #NULL! | BA7: #NULL! | BC7: #NULL! | BD7: #NULL! | BE7: #NULL! | BF7: #NULL! | BG7: 9 | BH7: #NULL! | BI7: #NULL! | BJ7: #NULL! | BK7: #NULL! | BL7: 2 | BM7: 7 | BN7: Don’t recall something about I don’t remember | BO7: 98 | BP7: #NULL! | BQ7: #NULL! | BR7: #NULL! | BS7: 5 | BT7: Nice music no message | BU7: 20 | BV7: #NULL! | BW7: #NULL! | BX7: #NULL! | BZ7: #NULL! | CA7: #NULL! | CB7: #NULL! | CC7: 2 | CD7: #NULL! | CE7: 1 | CF7: 1 | CG7: 1 | CH7: I need to pay both bills, the light and water and waste water. I had been unable to log into my online account. Car said I don’t remember her name. She was patient and she walked me through what the issue was and was able to fix it. I was a very satisfied. | CI7: 1 | CJ7: #NULL! | CK7: #NULL! | CL7: 9 | CN7: #NULL! | CO7: #NULL! | CP7: #NULL! | CQ7: 2 | CR7: #NULL! | CS7: 10 | CT7: 10 | CU7: 10 | CV7: 10 | CW7: 10 | CX7: 10 | CY7: 10 | DA7: #NULL! | DB7: #NULL! | DC7: 10 | DD7: #NULL! | DE7: #NULL! | DF7: #NULL! | DG7: #NULL! | DH7: #NULL! | DI7: #NULL! | DJ7: #NULL! | DK7: #NULL! | DL7: #NULL! | DN7: 1 | DP7: #NULL! | DQ7: #NULL! | DR7: #NULL! | DT7: #NULL! | DU7: #NULL! | DV7: #NULL! | DW7: 5 | DX7: 2 | DZ7: #NULL! | EA7: #NULL! | EI7: #NULL! | EJ7: #NULL! | EK7: #NULL! | EL7: #NULL! | EM7: 9 | EN7: 3 | EP7: 1 | EQ7: 3 | ER7: 2 | ES7: 78745 | ET7: 2 | EU7: 4 | EV7: 4 | EW7: 5 | EX7: 2 | EY7: Yolanda | EZ7: Arriaga | FB7: yoarriaga07@Yahoo.com | FC7: 5124131966 | FD7: #NULL! | FE7: #NULL! | FF7: 3 | FH7: 12 Aug 2025 - 12:05:53 CDT | FI7: 12573
A8: 37 | B8: 1 | C8: 2 | D8: 1 | E8: #NULL! | F8: 2 | G8: 2 | H8: 2 | J8: 1 | K8: 14 | N8: Nest thermostat program | P8: #NULL! | Q8: #NULL! | R8: #NULL! | S8: #NULL! | T8: 10 | U8: 10 | V8: 10 | W8: 9 | Y8: #NULL! | Z8: #NULL! | AA8: #NULL! | AB8: #NULL! | AC8: Clear instructions | AD8: 30 | AE8: #NULL! | AF8: #NULL! | AG8: #NULL! | AI8: #NULL! | AJ8: #NULL! | AK8: #NULL! | AL8: #NULL! | AM8: Got me to appropriate person | AN8: 22 | AO8: #NULL! | AP8: #NULL! | AQ8: #NULL! | AS8: #NULL! | AT8: #NULL! | AU8: #NULL! | AV8: #NULL! | AW8: Easy to use | AX8: 27 | AY8: #NULL! | AZ8: #NULL! | BA8: #NULL! | BC8: #NULL! | BD8: #NULL! | BE8: #NULL! | BF8: #NULL! | BG8: Did not take long | BH8: 21 | BI8: #NULL! | BJ8: #NULL! | BK8: #NULL! | BL8: 5 | BM8: 10 | BN8: Don’t remember | BO8: 98 | BP8: #NULL! | BQ8: #NULL! | BR8: #NULL! | BS8: 10 | BT8: No other messages | BU8: 97 | BV8: #NULL! | BW8: #NULL! | BX8: #NULL! | BZ8: #NULL! | CA8: #NULL! | CB8: #NULL! | CC8: 2 | CD8: #NULL! | CE8: 1 | CF8: 1 | CG8: 2 | CH8: They had someone call me back | CI8: 2 | CJ8: #NULL! | CK8: #NULL! | CL8: 10 | CN8: #NULL! | CO8: #NULL! | CP8: #NULL! | CQ8: 2 | CR8: #NULL! | CS8: 10 | CT8: 10 | CU8: 10 | CV8: 11 | CW8: 10 | CX8: 10 | CY8: 9 | DA8: #NULL! | DB8: #NULL! | DC8: 10 | DD8: #NULL! | DE8: #NULL! | DF8: #NULL! | DG8: #NULL! | DH8: #NULL! | DI8: #NULL! | DJ8: #NULL! | DK8: #NULL! | DL8: #NULL! | DN8: 1 | DP8: #NULL! | DQ8: #NULL! | DR8: #NULL! | DT8: #NULL! | DU8: #NULL! | DV8: #NULL! | DW8: 2 | DX8: 2 | DZ8: #NULL! | EA8: #NULL! | EI8: #NULL! | EJ8: #NULL! | EK8: #NULL! | EL8: #NULL! | EM8: 10 | EN8: 1 | EP8: 5 | EQ8: 3 | ER8: 1 | ES8: 78701 | ET8: 1 | EU8: 4 | EV8: 5 | EW8: 5 | EX8: 1 | EY8: Gary | EZ8: Watkins | FB8: garywatkins@protonmail.com | FC8: 5126729678 | FD8: #NULL! | FE8: #NULL! | FF8: 3 | FH8: 17 Aug 2025 - 16:43:05 CDT | FI8: 12617
A9: 58 | B9: 1 | C9: 2 | D9: 1 | E9: #NULL! | F9: 2 | G9: 2 | H9: 1 | J9: 2 | K9: 2 | O9: Our trash can has been missed on numerous occasions. I’ve had to call for a pick up about 4-5 times in this year alone. I requested some sort of credit for our inconvenience but never received a response to that. They did send someone to clear out our trash with the next day though. | P9: 12 | Q9: #NULL! | R9: #NULL! | S9: #NULL! | T9: 9 | U9: 8 | V9: 8 | W9: 9 | Y9: #NULL! | Z9: #NULL! | AA9: #NULL! | AB9: #NULL! | AC9: 8 | AD9: #NULL! | AE9: #NULL! | AF9: #NULL! | AG9: #NULL! | AI9: #NULL! | AJ9: #NULL! | AK9: #NULL! | AL9: #NULL! | AM9: 8 | AN9: #NULL! | AO9: #NULL! | AP9: #NULL! | AQ9: #NULL! | AS9: #NULL! | AT9: #NULL! | AU9: #NULL! | AV9: #NULL! | AW9: 8 | AX9: #NULL! | AY9: #NULL! | AZ9: #NULL! | BA9: #NULL! | BC9: #NULL! | BD9: #NULL! | BE9: #NULL! | BF9: #NULL! | BG9: 8 | BH9: #NULL! | BI9: #NULL! | BJ9: #NULL! | BK9: #NULL! | BL9: 2 | BM9: 5 | BN9: A constant loop asking if I or someone in my household was on life support. | BO9: 99 | BP9: #NULL! | BQ9: #NULL! | BR9: #NULL! | BS9: 3 | BT9: Rates are stable for the next quarter or on the opposite side, rates are expected to increase in the next quarter due to xyzzy… | BU9: 1 | BV9: #NULL! | BW9: #NULL! | BX9: #NULL! | BZ9: #NULL! | CA9: #NULL! | CB9: #NULL! | CC9: 1 | CD9: 8 | CE9: 2 | CF9: #NULL! | CG9: #NULL! | CI9: #NULL! | CJ9: #NULL! | CK9: #NULL! | CL9: #NULL! | CN9: #NULL! | CO9: #NULL! | CP9: #NULL! | CQ9: 2 | CR9: #NULL! | CS9: 10 | CT9: 10 | CU9: 9 | CV9: 8 | CW9: 9 | CX9: 9 | CY9: 10 | DA9: #NULL! | DB9: #NULL! | DC9: 9 | DD9: #NULL! | DE9: #NULL! | DF9: #NULL! | DG9: #NULL! | DH9: #NULL! | DI9: #NULL! | DJ9: #NULL! | DK9: #NULL! | DL9: #NULL! | DN9: 1 | DP9: #NULL! | DQ9: #NULL! | DR9: #NULL! | DT9: #NULL! | DU9: #NULL! | DV9: #NULL! | DW9: 2 | DX9: 2 | DZ9: #NULL! | EA9: #NULL! | EI9: #NULL! | EJ9: #NULL! | EK9: #NULL! | EL9: #NULL! | EM9: 8 | EN9: 3 | EP9: 1 | EQ9: 1 | ER9: 2 | ES9: 78660 | ET9: 4 | EU9: 3 | EV9: 6 | EW9: 5 | EX9: 2 | EY9: Amelia | EZ9: De La Rosa-Rodriguez | FB9: arodriguez2052@yahoo.com | FC9: 5129252012 | FD9: #NULL! | FE9: #NULL! | FF9: 2 | FH9: 08 Sep 2025 - 15:13:44 CDT | FI9: 10637
A10: 61 | B10: 1 | C10: 2 | D10: 1 | E10: #NULL! | F10: 2 | G10: 2 | H10: 4 | I10: Moving questions | J10: 1 | K10: 6 | P10: #NULL! | Q10: #NULL! | R10: #NULL! | S10: #NULL! | T10: 10 | U10: 10 | V10: 10 | W10: 10 | Y10: #NULL! | Z10: #NULL! | AA10: #NULL! | AB10: #NULL! | AC10: 10 | AD10: #NULL! | AE10: #NULL! | AF10: #NULL! | AG10: #NULL! | AI10: #NULL! | AJ10: #NULL! | AK10: #NULL! | AL10: #NULL! | AM10: 10 | AN10: #NULL! | AO10: #NULL! | AP10: #NULL! | AQ10: #NULL! | AS10: #NULL! | AT10: #NULL! | AU10: #NULL! | AV10: #NULL! | AW10: 10 | AX10: #NULL! | AY10: #NULL! | AZ10: #NULL! | BA10: #NULL! | BC10: #NULL! | BD10: #NULL! | BE10: #NULL! | BF10: #NULL! | BG10: 10 | BH10: #NULL! | BI10: #NULL! | BJ10: #NULL! | BK10: #NULL! | BL10: 1 | BM10: #NULL! | BO10: #NULL! | BP10: #NULL! | BQ10: #NULL! | BR10: #NULL! | BS10: #NULL! | BU10: #NULL! | BV10: #NULL! | BW10: #NULL! | BX10: #NULL! | BZ10: #NULL! | CA10: #NULL! | CB10: #NULL! | CC10: 2 | CD10: #NULL! | CE10: 2 | CF10: #NULL! | CG10: #NULL! | CI10: #NULL! | CJ10: #NULL! | CK10: #NULL! | CL10: #NULL! | CN10: #NULL! | CO10: #NULL! | CP10: #NULL! | CQ10: 2 | CR10: #NULL! | CS10: 10 | CT10: 10 | CU10: 10 | CV10: 10 | CW10: 10 | CX10: 10 | CY10: 10 | DA10: #NULL! | DB10: #NULL! | DC10: 10 | DD10: #NULL! | DE10: #NULL! | DF10: #NULL! | DG10: #NULL! | DH10: #NULL! | DI10: #NULL! | DJ10: #NULL! | DK10: #NULL! | DL10: #NULL! | DN10: 1 | DP10: #NULL! | DQ10: #NULL! | DR10: #NULL! | DT10: #NULL! | DU10: #NULL! | DV10: #NULL! | DW10: 3 | DX10: 1 | DY10: Just get notice though email of saving energy | DZ10: 99 | EA10: #NULL! | EI10: #NULL! | EJ10: #NULL! | EK10: #NULL! | EL10: #NULL! | EM10: 4 | EN10: 3 | EP10: 1 | EQ10: 1 | ER10: 1 | ES10: 78729 | ET10: 5 | EU10: 1 | EV10: 4 | EW10: 4 | EX10: 2 | EY10: Areli | EZ10: Dauphin | FB10: Arelimguerrero@gmail.com | FC10: 5125847314 | FD10: #NULL! | FE10: #NULL! | FF10: 1 | FH10: 08 Sep 2025 - 15:13:34 CDT | FI10: 1286
A11: 64 | B11: 1 | C11: 2 | D11: 1 | E11: #NULL! | F11: 2 | G11: 2 | H11: 2 | J11: 2 | K11: 23 | O11: Meter on my house seems way out of line with actual electricity used. | P11: 1 | Q11: #NULL! | R11: #NULL! | S11: #NULL! | T11: 2 | U11: 1 | V11: 5 | W11: 2 | X11: Not helpful | Y11: 6 | Z11: #NULL! | AA11: #NULL! | AB11: #NULL! | AD11: #NULL! | AE11: #NULL! | AF11: #NULL! | AG11: #NULL! | AH11: Not helpful | AI11: 6 | AJ11: #NULL! | AK11: #NULL! | AL11: #NULL! | AN11: #NULL! | AO11: #NULL! | AP11: #NULL! | AQ11: #NULL! | AS11: #NULL! | AT11: #NULL! | AU11: #NULL! | AV11: #NULL! | AX11: #NULL! | AY11: #NULL! | AZ11: #NULL! | BA11: #NULL! | BB11: Long wait time | BC11: 2 | BD11: #NULL! | BE11: #NULL! | BF11: #NULL! | BH11: #NULL! | BI11: #NULL! | BJ11: #NULL! | BK11: #NULL! | BL11: 2 | BM11: 9 | BN11: No idea | BO11: 98 | BP11: #NULL! | BQ11: #NULL! | BR11: #NULL! | BS11: 10 | BT11: That would be it | BU11: 97 | BV11: #NULL! | BW11: #NULL! | BX11: #NULL! | BZ11: #NULL! | CA11: #NULL! | CB11: #NULL! | CC11: 1 | CD11: 4 | CE11: 1 | CF11: 1 | CG11: 2 | CH11: Meter reading seems crazy off, but never got any help | CI11: 1 | CJ11: #NULL! | CK11: #NULL! | CL11: 4 | CM11: Find someone who understands my kind of meter and why it is showing such high usage | CN11: 3 | CO11: #NULL! | CP11: #NULL! | CQ11: 2 | CR11: #NULL! | CS11: 9 | CT11: 9 | CU11: 1 | CV11: 3 | CW11: 5 | CX11: 9 | CY11: 9 | CZ11: Fix the meter issue | DA11: 2 | DB11: #NULL! | DC11: 3 | DD11: 1 | DE11: 1 | DF11: 0 | DG11: 0 | DH11: 0 | DI11: 1 | DJ11: 0 | DK11: 1 | DL11: 0 | DN11: 2 | DO11: Someone with knowledge of the meter and why readings are so high | DP11: 5 | DQ11: #NULL! | DR11: #NULL! | DT11: #NULL! | DU11: #NULL! | DV11: #NULL! | DW11: 1 | DX11: 2 | DZ11: #NULL! | EA11: #NULL! | EI11: #NULL! | EJ11: #NULL! | EK11: #NULL! | EL11: #NULL! | EM11: 6 | EN11: 1 | EP11: 1 | EQ11: 1 | ER11: 2 | ES11: 78735 | ET11: 4 | EU11: 4 | EV11: 6 | EW11: 5 | EX11: 1 | EY11: Brian | EZ11: Cobb | FB11: brian@cobbmechanical.com | FC11: 5129172998 | FD11: #NULL! | FE11: #NULL! | FF11: 2 | FH11: 08 Sep 2025 - 15:35:26 CDT | FI11: 3192
A12: 76 | B12: 1 | C12: 2 | D12: 1 | E12: #NULL! | F12: 2 | G12: 2 | H12: 3 | J12: 1 | K12: 12 | L12: Water leak caused by work on main line that blew my meter to house line | P12: #NULL! | Q12: #NULL! | R12: #NULL! | S12: #NULL! | T12: 6 | U12: 8 | V12: 5 | W12: 9 | Y12: #NULL! | Z12: #NULL! | AA12: #NULL! | AB12: #NULL! | AD12: #NULL! | AE12: #NULL! | AF12: #NULL! | AG12: #NULL! | AI12: #NULL! | AJ12: #NULL! | AK12: #NULL! | AL12: #NULL! | AM12: Although it took several hours, we were able to determine how I could receive a partial credit | AN12: 25 | AO12: #NULL! | AP12: #NULL! | AQ12: #NULL! | AS12: #NULL! | AT12: #NULL! | AU12: #NULL! | AV12: #NULL! | AX12: #NULL! | AY12: #NULL! | AZ12: #NULL! | BA12: #NULL! | BC12: #NULL! | BD12: #NULL! | BE12: #NULL! | BF12: #NULL! | BG12: I was served and supported by a great customer service team, as I spoke to more than one person | BH12: 24 | BI12: 25 | BJ12: #NULL! | BK12: #NULL! | BL12: 1 | BM12: #NULL! | BO12: #NULL! | BP12: #NULL! | BQ12: #NULL! | BR12: #NULL! | BS12: #NULL! | BU12: #NULL! | BV12: #NULL! | BW12: #NULL! | BX12: #NULL! | BZ12: #NULL! | CA12: #NULL! | CB12: #NULL! | CC12: 1 | CD12: 7 | CE12: 1 | CF12: 1 | CG12: 1 | CH12: I cannot remember the specific reason | CI12: 98 | CJ12: #NULL! | CK12: #NULL! | CL12: 10 | CN12: #NULL! | CO12: #NULL! | CP12: #NULL! | CQ12: 1 | CR12: 9 | CS12: 10 | CT12: 8 | CU12: 8 | CV12: 9 | CW12: 6 | CX12: 9 | CY12: 10 | DA12: #NULL! | DB12: #NULL! | DC12: 10 | DD12: #NULL! | DE12: #NULL! | DF12: #NULL! | DG12: #NULL! | DH12: #NULL! | DI12: #NULL! | DJ12: #NULL! | DK12: #NULL! | DL12: #NULL! | DN12: 1 | DP12: #NULL! | DQ12: #NULL! | DR12: #NULL! | DT12: #NULL! | DU12: #NULL! | DV12: #NULL! | DW12: 1 | DX12: 2 | DZ12: #NULL! | EA12: #NULL! | EI12: #NULL! | EJ12: #NULL! | EK12: #NULL! | EL12: #NULL! | EM12: 6 | EN12: 1 | EP12: 1 | EQ12: 1 | ER12: 2 | ES12: 78750 | ET12: 2 | EU12: 5 | EV12: 6 | EW12: 5 | EX12: 1 | EY12: Christian | EZ12: Patrik | FB12: Christianjpatrik@gmail.com | FC12: 512-560-1894 | FD12: #NULL! | FE12: #NULL! | FF12: 1 | FH12: 08 Sep 2025 - 16:39:12 CDT | FI12: 8864
A13: 78 | B13: 1 | C13: 2 | D13: 1 | E13: #NULL! | F13: 2 | G13: 2 | H13: 2 | J13: 1 | K13: 33 | N13: Auto payment options on bill | P13: #NULL! | Q13: #NULL! | R13: #NULL! | S13: #NULL! | T13: 10 | U13: 10 | V13: 10 | W13: 7 | Y13: #NULL! | Z13: #NULL! | AA13: #NULL! | AB13: #NULL! | AC13: Seamless | AD13: 21 | AE13: #NULL! | AF13: #NULL! | AG13: #NULL! | AI13: #NULL! | AJ13: #NULL! | AK13: #NULL! | AL13: #NULL! | AM13: Agent knew exactly what was required to solve my issue | AN13: 25 | AO13: #NULL! | AP13: #NULL! | AQ13: #NULL! | AS13: #NULL! | AT13: #NULL! | AU13: #NULL! | AV13: #NULL! | AW13: She was excellent | AX13: 24 | AY13: #NULL! | AZ13: #NULL! | BA13: #NULL! | BC13: #NULL! | BD13: #NULL! | BE13: #NULL! | BF13: #NULL! | BH13: #NULL! | BI13: #NULL! | BJ13: #NULL! | BK13: #NULL! | BL13: 2 | BM13: 7 | BN13: Don’t | BO13: 98 | BP13: #NULL! | BQ13: #NULL! | BR13: #NULL! | BS13: 10 | BT13: None | BU13: 97 | BV13: #NULL! | BW13: #NULL! | BX13: #NULL! | BZ13: #NULL! | CA13: #NULL! | CB13: #NULL! | CC13: 1 | CD13: 8 | CE13: 2 | CF13: #NULL! | CG13: #NULL! | CI13: #NULL! | CJ13: #NULL! | CK13: #NULL! | CL13: #NULL! | CN13: #NULL! | CO13: #NULL! | CP13: #NULL! | CQ13: 2 | CR13: #NULL! | CS13: 10 | CT13: 10 | CU13: 10 | CV13: 10 | CW13: 10 | CX13: 10 | CY13: 10 | DA13: #NULL! | DB13: #NULL! | DC13: 10 | DD13: #NULL! | DE13: #NULL! | DF13: #NULL! | DG13: #NULL! | DH13: #NULL! | DI13: #NULL! | DJ13: #NULL! | DK13: #NULL! | DL13: #NULL! | DN13: 1 | DP13: #NULL! | DQ13: #NULL! | DR13: #NULL! | DT13: #NULL! | DU13: #NULL! | DV13: #NULL! | DW13: 3 | DX13: 2 | DZ13: #NULL! | EA13: #NULL! | EI13: #NULL! | EJ13: #NULL! | EK13: #NULL! | EL13: #NULL! | EM13: 6 | EN13: 1 | EP13: 5 | EQ13: 1 | ER13: 2 | ES13: 78731 | ET13: 2 | EU13: 5 | EV13: 6 | EW13: 5 | EX13: 1 | EY13: Andrew | EZ13: Rhodes | FB13: arhodes0@gmail.com | FC13: 6504419499 | FD13: #NULL! | FE13: #NULL! | FF13: 2 | FH13: 08 Sep 2025 - 16:46:40 CDT | FI13: 4384
A14: 79 | B14: 1 | C14: 2 | D14: 1 | E14: #NULL! | F14: 2 | G14: 2 | H14: 1 | J14: 1 | K14: 14 | N14: Recycling | P14: #NULL! | Q14: #NULL! | R14: #NULL! | S14: #NULL! | T14: 10 | U14: 10 | V14: 10 | W14: 10 | Y14: #NULL! | Z14: #NULL! | AA14: #NULL! | AB14: #NULL! | AC14: 10 | AD14: #NULL! | AE14: #NULL! | AF14: #NULL! | AG14: #NULL! | AI14: #NULL! | AJ14: #NULL! | AK14: #NULL! | AL14: #NULL! | AM14: 10 | AN14: #NULL! | AO14: #NULL! | AP14: #NULL! | AQ14: #NULL! | AS14: #NULL! | AT14: #NULL! | AU14: #NULL! | AV14: #NULL! | AW14: 10 | AX14: #NULL! | AY14: #NULL! | AZ14: #NULL! | BA14: #NULL! | BC14: #NULL! | BD14: #NULL! | BE14: #NULL! | BF14: #NULL! | BG14: 10 | BH14: #NULL! | BI14: #NULL! | BJ14: #NULL! | BK14: #NULL! | BL14: 1 | BM14: #NULL! | BO14: #NULL! | BP14: #NULL! | BQ14: #NULL! | BR14: #NULL! | BS14: #NULL! | BU14: #NULL! | BV14: #NULL! | BW14: #NULL! | BX14: #NULL! | BZ14: #NULL! | CA14: #NULL! | CB14: #NULL! | CC14: 2 | CD14: #NULL! | CE14: 2 | CF14: #NULL! | CG14: #NULL! | CI14: #NULL! | CJ14: #NULL! | CK14: #NULL! | CL14: #NULL! | CN14: #NULL! | CO14: #NULL! | CP14: #NULL! | CQ14: 2 | CR14: #NULL! | CS14: 10 | CT14: 10 | CU14: 10 | CV14: 10 | CW14: 10 | CX14: 10 | CY14: 10 | DA14: #NULL! | DB14: #NULL! | DC14: 10 | DD14: #NULL! | DE14: #NULL! | DF14: #NULL! | DG14: #NULL! | DH14: #NULL! | DI14: #NULL! | DJ14: #NULL! | DK14: #NULL! | DL14: #NULL! | DN14: 1 | DP14: #NULL! | DQ14: #NULL! | DR14: #NULL! | DT14: #NULL! | DU14: #NULL! | DV14: #NULL! | DW14: 2 | DX14: 2 | DZ14: #NULL! | EA14: #NULL! | EI14: #NULL! | EJ14: #NULL! | EK14: #NULL! | EL14: #NULL! | EM14: 10 | EN14: 1 | EP14: 5 | EQ14: 5 | ER14: 1 | ES14: 78759 | ET14: 3 | EU14: 4 | EV14: 2 | EW14: 5 | EX14: 2 | EY14: Audrey | EZ14: Johnson | FB14: audrey.johson71@gmail.com | FC14: 512-810-8065 | FD14: #NULL! | FE14: #NULL! | FF14: 1 | FH14: 08 Sep 2025 - 16:52:33 CDT | FI14: 2547
A15: 83 | B15: 1 | C15: 2 | D15: 1 | E15: #NULL! | F15: 2 | G15: 2 | H15: 4 | I15: Clean community fee and what city services it applies to, maintenance on street lighting | J15: 1 | K15: 20 | P15: #NULL! | Q15: #NULL! | R15: #NULL! | S15: #NULL! | T15: 3 | U15: 10 | V15: 6 | W15: 10 | X15: This is more an issue with Austin 311. Austin energy was able to look up the info for the clean community fee and clarify that it does cover bulk pickup and dead animal removal for condominiums, but city employees did not believe me until I got a 3-way call with Austin energy and a 311 representative on the line at the same time. | Y15: 5 | Z15: #NULL! | AA15: #NULL! | AB15: #NULL! | AD15: #NULL! | AE15: #NULL! | AF15: #NULL! | AG15: #NULL! | AI15: #NULL! | AJ15: #NULL! | AK15: #NULL! | AL15: #NULL! | AM15: Austin energy employees were able to locate the correct information for my inquiry. I consider this a high level of service as other companies often have representatives not empowered to make changes to accounts or gather necessary information. | AN15: 30 | AO15: #NULL! | AP15: #NULL! | AQ15: #NULL! | AS15: #NULL! | AT15: #NULL! | AU15: #NULL! | AV15: #NULL! | AX15: #NULL! | AY15: #NULL! | AZ15: #NULL! | BA15: #NULL! | BC15: #NULL! | BD15: #NULL! | BE15: #NULL! | BF15: #NULL! | BG15: Austin energy was able to answer my call and respond in a reasonable amount of time on the phone. I consider this a very good level of service, especially as other companies or services become difficult to reach | BH15: 22 | BI15: #NULL! | BJ15: #NULL! | BK15: #NULL! | BL15: 2 | BM15: 4 | BN15: I’m sorry, I don’t remember the exact path through the phone tree. This was a complex call to multiple city agencies including call forwarding and a 3-way conversation and was resolved in about 30 minutes total. Difficult but achievable for the average customer. | BO15: 98 | BP15: #NULL! | BQ15: #NULL! | BR15: #NULL! | BS15: 7 | BT15: A phone tree option to leave a brief message with description of the issue and receive a callback if hold time were to exceed a few minutes. | BU15: 13 | BV15: #NULL! | BW15: #NULL! | BX15: #NULL! | BZ15: #NULL! | CA15: #NULL! | CB15: #NULL! | CC15: 1 | CD15: 10 | CE15: 1 | CF15: 1 | CG15: 1 | CH15: Yes. The representative need to look up information and contact another agency to inform them of their findings. | CI15: 1 | CJ15: #NULL! | CK15: #NULL! | CL15: 10 | CN15: #NULL! | CO15: #NULL! | CP15: #NULL! | CQ15: 2 | CR15: #NULL! | CS15: 10 | CT15: 10 | CU15: 10 | CV15: 10 | CW15: 10 | CX15: 10 | CY15: 10 | DA15: #NULL! | DB15: #NULL! | DC15: 10 | DD15: #NULL! | DE15: #NULL! | DF15: #NULL! | DG15: #NULL! | DH15: #NULL! | DI15: #NULL! | DJ15: #NULL! | DK15: #NULL! | DL15: #NULL! | DN15: 1 | DP15: #NULL! | DQ15: #NULL! | DR15: #NULL! | DT15: #NULL! | DU15: #NULL! | DV15: #NULL! | DW15: 4 | DX15: 1 | DY15: I receive paper bills from Austin energy. The included information advised me of billing changes. These were used to update the budget for a condo association to good effect. | DZ15: 3 | EA15: #NULL! | EI15: #NULL! | EJ15: #NULL! | EK15: #NULL! | EL15: #NULL! | EM15: 4 | EN15: 1 | EP15: 1 | EQ15: 2 | ER15: 2 | ES15: 78704 | ET15: 1 | EU15: 5 | EV15: 6 | EW15: 5 | EX15: 1 | EY15: David | EZ15: Craven | FB15: cascraven@gmail.com | FC15: 5408186726 | FD15: #NULL! | FE15: #NULL! | FF15: 2 | FH15: 08 Sep 2025 - 17:41:00 CDT | FI15: 3209
A16: 86 | B16: 1 | C16: 2 | D16: 1 | E16: #NULL! | F16: 2 | G16: 2 | H16: 2 | J16: 1 | K16: 3 | P16: #NULL! | Q16: #NULL! | R16: #NULL! | S16: #NULL! | T16: 10 | U16: 10 | V16: 10 | W16: 10 | Y16: #NULL! | Z16: #NULL! | AA16: #NULL! | AB16: #NULL! | AC16: 10 | AD16: #NULL! | AE16: #NULL! | AF16: #NULL! | AG16: #NULL! | AI16: #NULL! | AJ16: #NULL! | AK16: #NULL! | AL16: #NULL! | AM16: 10 | AN16: #NULL! | AO16: #NULL! | AP16: #NULL! | AQ16: #NULL! | AS16: #NULL! | AT16: #NULL! | AU16: #NULL! | AV16: #NULL! | AW16: 10 | AX16: #NULL! | AY16: #NULL! | AZ16: #NULL! | BA16: #NULL! | BC16: #NULL! | BD16: #NULL! | BE16: #NULL! | BF16: #NULL! | BG16: 10 | BH16: #NULL! | BI16: #NULL! | BJ16: #NULL! | BK16: #NULL! | BL16: 1 | BM16: #NULL! | BO16: #NULL! | BP16: #NULL! | BQ16: #NULL! | BR16: #NULL! | BS16: #NULL! | BU16: #NULL! | BV16: #NULL! | BW16: #NULL! | BX16: #NULL! | BZ16: #NULL! | CA16: #NULL! | CB16: #NULL! | CC16: 1 | CD16: 10 | CE16: 2 | CF16: #NULL! | CG16: #NULL! | CI16: #NULL! | CJ16: #NULL! | CK16: #NULL! | CL16: #NULL! | CN16: #NULL! | CO16: #NULL! | CP16: #NULL! | CQ16: 2 | CR16: #NULL! | CS16: 10 | CT16: 10 | CU16: 10 | CV16: 10 | CW16: 10 | CX16: 10 | CY16: 10 | DA16: #NULL! | DB16: #NULL! | DC16: 10 | DD16: #NULL! | DE16: #NULL! | DF16: #NULL! | DG16: #NULL! | DH16: #NULL! | DI16: #NULL! | DJ16: #NULL! | DK16: #NULL! | DL16: #NULL! | DN16: 1 | DP16: #NULL! | DQ16: #NULL! | DR16: #NULL! | DT16: #NULL! | DU16: #NULL! | DV16: #NULL! | DW16: 3 | DX16: 2 | DZ16: #NULL! | EA16: #NULL! | EI16: #NULL! | EJ16: #NULL! | EK16: #NULL! | EL16: #NULL! | EM16: 9 | EN16: 3 | EP16: 5 | EQ16: 3 | ER16: 2 | ES16: 78724 | ET16: 1 | EU16: 3 | EV16: 2 | EW16: 5 | EX16: 1 | EY16: Joe | EZ16: Altamirano Jr | FB16: cjimtheboss@gmail.com | FC16: 737-888-4223 | FD16: #NULL! | FE16: #NULL! | FF16: 1 | FH16: 08 Sep 2025 - 18:49:22 CDT | FI16: 8868
A17: 91 | B17: 1 | C17: 2 | D17: 1 | E17: #NULL! | F17: 3 | G17: 2 | H17: 3 | J17: 1 | K17: 21 | P17: #NULL! | Q17: #NULL! | R17: #NULL! | S17: #NULL! | T17: 10 | U17: 10 | V17: 10 | W17: 10 | Y17: #NULL! | Z17: #NULL! | AA17: #NULL! | AB17: #NULL! | AC17: Easy to follow | AD17: 20 | AE17: #NULL! | AF17: #NULL! | AG17: #NULL! | AI17: #NULL! | AJ17: #NULL! | AK17: #NULL! | AL17: #NULL! | AM17: Easy to follow | AN17: 27 | AO17: #NULL! | AP17: #NULL! | AQ17: #NULL! | AS17: #NULL! | AT17: #NULL! | AU17: #NULL! | AV17: #NULL! | AW17: Easy to follow | AX17: 22 | AY17: #NULL! | AZ17: #NULL! | BA17: #NULL! | BC17: #NULL! | BD17: #NULL! | BE17: #NULL! | BF17: #NULL! | BG17: Easy to follow | BH17: 27 | BI17: #NULL! | BJ17: #NULL! | BK17: #NULL! | BL17: 2 | BM17: 7 | BN17: Can’t remember | BO17: 98 | BP17: #NULL! | BQ17: #NULL! | BR17: #NULL! | BS17: 10 | BT17: How can save more energy tips | BU17: 8 | BV17: #NULL! | BW17: #NULL! | BX17: #NULL! | BZ17: #NULL! | CA17: #NULL! | CB17: #NULL! | CC17: 3 | CD17: #NULL! | CE17: 1 | CF17: 1 | CG17: 1 | CH17: Can’t remember | CI17: 98 | CJ17: #NULL! | CK17: #NULL! | CL17: 7 | CM17: Google to where I may get the answer | CN17: 99 | CO17: #NULL! | CP17: #NULL! | CQ17: 2 | CR17: #NULL! | CS17: 8 | CT17: 8 | CU17: 8 | CV17: 8 | CW17: 8 | CX17: 8 | CY17: 8 | DA17: #NULL! | DB17: #NULL! | DC17: 6 | DD17: 0 | DE17: 0 | DF17: 1 | DG17: 0 | DH17: 0 | DI17: 0 | DJ17: 0 | DK17: 0 | DL17: 0 | DN17: 1 | DP17: #NULL! | DQ17: #NULL! | DR17: #NULL! | DT17: #NULL! | DU17: #NULL! | DV17: #NULL! | DW17: 2 | DX17: 2 | DZ17: #NULL! | EA17: #NULL! | EI17: #NULL! | EJ17: #NULL! | EK17: #NULL! | EL17: #NULL! | EM17: 10 | EN17: 1 | EP17: 5 | EQ17: 5 | ER17: 2 | ES17: 78749 | ET17: 2 | EU17: 5 | EV17: 2 | EW17: 5 | EX17: 2 | EY17: Vonnie | EZ17: Basham | FB17: Bashamvonnie@gmail.com | FC17: 5128612079 | FD17: #NULL! | FE17: #NULL! | FF17: 2 | FH17: 08 Sep 2025 - 21:13:21 CDT | FI17: 3169
A18: 103 | B18: 1 | C18: 2 | D18: 1 | E18: #NULL! | F18: 2 | G18: 2 | H18: 3 | J18: 1 | K18: 1 | P18: #NULL! | Q18: #NULL! | R18: #NULL! | S18: 10 | T18: 10 | U18: 10 | V18: 10 | W18: 10 | Y18: #NULL! | Z18: #NULL! | AA18: #NULL! | AB18: #NULL! | AC18: 10 | AD18: #NULL! | AE18: #NULL! | AF18: #NULL! | AG18: #NULL! | AI18: #NULL! | AJ18: #NULL! | AK18: #NULL! | AL18: #NULL! | AM18: 10 | AN18: #NULL! | AO18: #NULL! | AP18: #NULL! | AQ18: #NULL! | AS18: #NULL! | AT18: #NULL! | AU18: #NULL! | AV18: #NULL! | AW18: 10 | AX18: #NULL! | AY18: #NULL! | AZ18: #NULL! | BA18: #NULL! | BC18: #NULL! | BD18: #NULL! | BE18: #NULL! | BF18: #NULL! | BG18: 10 | BH18: #NULL! | BI18: #NULL! | BJ18: #NULL! | BK18: #NULL! | BL18: 2 | BM18: 2 | BN18: Don’t remember | BO18: 98 | BP18: #NULL! | BQ18: #NULL! | BR18: #NULL! | BS18: 1 | BT18: Not sure | BU18: 98 | BV18: #NULL! | BW18: #NULL! | BX18: #NULL! | BZ18: #NULL! | CA18: #NULL! | CB18: #NULL! | CC18: 2 | CD18: #NULL! | CE18: 1 | CF18: 1 | CG18: 1 | CH18: Don’t remember | CI18: 98 | CJ18: #NULL! | CK18: #NULL! | CL18: 10 | CN18: #NULL! | CO18: #NULL! | CP18: #NULL! | CQ18: 2 | CR18: #NULL! | CS18: 10 | CT18: 10 | CU18: 10 | CV18: 10 | CW18: 10 | CX18: 10 | CY18: 10 | DA18: #NULL! | DB18: #NULL! | DC18: 10 | DD18: #NULL! | DE18: #NULL! | DF18: #NULL! | DG18: #NULL! | DH18: #NULL! | DI18: #NULL! | DJ18: #NULL! | DK18: #NULL! | DL18: #NULL! | DN18: 1 | DP18: #NULL! | DQ18: #NULL! | DR18: #NULL! | DT18: #NULL! | DU18: #NULL! | DV18: #NULL! | DW18: 3 | DX18: 2 | DZ18: #NULL! | EA18: #NULL! | EI18: #NULL! | EJ18: #NULL! | EK18: #NULL! | EL18: #NULL! | EM18: 8 | EN18: 1 | EP18: 1 | EQ18: 1 | ER18: 2 | ES18: 78759 | ET18: 4 | EU18: 4 | EV18: 6 | EW18: 5 | EX18: 1 | EY18: Salman | EZ18: Khan | FB18: denpesar@me.com | FC18: 6462635204 | FD18: #NULL! | FE18: #NULL! | FF18: 1 | FH18: 09 Sep 2025 - 07:27:52 CDT | FI18: 10156
A19: 106 | B19: 1 | C19: 2 | D19: 1 | E19: #NULL! | F19: 2 | G19: 2 | H19: 2 | J19: 1 | K19: 3 | P19: #NULL! | Q19: #NULL! | R19: #NULL! | S19: #NULL! | T19: 6 | U19: 7 | V19: 7 | W19: 6 | Y19: #NULL! | Z19: #NULL! | AA19: #NULL! | AB19: #NULL! | AD19: #NULL! | AE19: #NULL! | AF19: #NULL! | AG19: #NULL! | AI19: #NULL! | AJ19: #NULL! | AK19: #NULL! | AL19: #NULL! | AN19: #NULL! | AO19: #NULL! | AP19: #NULL! | AQ19: #NULL! | AS19: #NULL! | AT19: #NULL! | AU19: #NULL! | AV19: #NULL! | AX19: #NULL! | AY19: #NULL! | AZ19: #NULL! | BA19: #NULL! | BC19: #NULL! | BD19: #NULL! | BE19: #NULL! | BF19: #NULL! | BH19: #NULL! | BI19: #NULL! | BJ19: #NULL! | BK19: #NULL! | BL19: 2 | BM19: 6 | BN19: Please wait for the next representative. I honestly don’t remember. | BO19: 6 | BP19: #NULL! | BQ19: #NULL! | BR19: #NULL! | BS19: 8 | BT19: Options to pay bill electronically | BU19: 2 | BV19: #NULL! | BW19: #NULL! | BX19: #NULL! | BZ19: #NULL! | CA19: #NULL! | CB19: #NULL! | CC19: 2 | CD19: #NULL! | CE19: 2 | CF19: #NULL! | CG19: #NULL! | CI19: #NULL! | CJ19: #NULL! | CK19: #NULL! | CL19: #NULL! | CN19: #NULL! | CO19: #NULL! | CP19: #NULL! | CQ19: 2 | CR19: #NULL! | CS19: 7 | CT19: 7 | CU19: 6 | CV19: 6 | CW19: 6 | CX19: 7 | CY19: 7 | CZ19: I think ways to pay bill electronically | DA19: 4 | DB19: #NULL! | DC19: 10 | DD19: #NULL! | DE19: #NULL! | DF19: #NULL! | DG19: #NULL! | DH19: #NULL! | DI19: #NULL! | DJ19: #NULL! | DK19: #NULL! | DL19: #NULL! | DN19: 1 | DP19: #NULL! | DQ19: #NULL! | DR19: #NULL! | DT19: #NULL! | DU19: #NULL! | DV19: #NULL! | DW19: 1 | DX19: 2 | DZ19: #NULL! | EA19: #NULL! | EI19: #NULL! | EJ19: #NULL! | EK19: #NULL! | EL19: #NULL! | EM19: 6 | EN19: 3 | EP19: 1 | EQ19: 2 | ER19: 1 | ES19: 78758 | ET19: 2 | EU19: 5 | EV19: 5 | EW19: 5 | EX19: 1 | EY19: David Augustine | EZ19: Ysla | FB19: daysla@icloud.com | FC19: 5129389484 | FD19: #NULL! | FE19: #NULL! | FF19: 1 | FH19: 09 Sep 2025 - 07:44:49 CDT | FI19: 3885
A20: 119 | B20: 1 | C20: 2 | D20: 1 | E20: #NULL! | F20: 2 | G20: 2 | H20: 2 | J20: 1 | K20: 18 | P20: #NULL! | Q20: #NULL! | R20: #NULL! | S20: #NULL! | T20: 8 | U20: 10 | V20: 10 | W20: 10 | Y20: #NULL! | Z20: #NULL! | AA20: #NULL! | AB20: #NULL! | AC20: Sometime the option to get a live agent is hard | AD20: 3 | AE20: #NULL! | AF20: #NULL! | AG20: #NULL! | AI20: #NULL! | AJ20: #NULL! | AK20: #NULL! | AL20: #NULL! | AM20: They explain it to me very well | AN20: 25 | AO20: #NULL! | AP20: #NULL! | AQ20: #NULL! | AS20: #NULL! | AT20: #NULL! | AU20: #NULL! | AV20: #NULL! | AW20: They are so nice | AX20: 24 | AY20: #NULL! | AZ20: #NULL! | BA20: #NULL! | BC20: #NULL! | BD20: #NULL! | BE20: #NULL! | BF20: #NULL! | BG20: Perfect | BH20: 28 | BI20: #NULL! | BJ20: #NULL! | BK20: #NULL! | BL20: 2 | BM20: 8 | BN20: I don't remember | BO20: 98 | BP20: #NULL! | BQ20: #NULL! | BR20: #NULL! | BS20: 11 | BT20: I don't remember | BU20: 98 | BV20: #NULL! | BW20: #NULL! | BX20: #NULL! | BZ20: #NULL! | CA20: #NULL! | CB20: #NULL! | CC20: 1 | CD20: 10 | CE20: 2 | CF20: #NULL! | CG20: #NULL! | CI20: #NULL! | CJ20: #NULL! | CK20: #NULL! | CL20: #NULL! | CN20: #NULL! | CO20: #NULL! | CP20: #NULL! | CQ20: 2 | CR20: #NULL! | CS20: 10 | CT20: 10 | CU20: 10 | CV20: 10 | CW20: 10 | CX20: 10 | CY20: 10 | DA20: #NULL! | DB20: #NULL! | DC20: 10 | DD20: #NULL! | DE20: #NULL! | DF20: #NULL! | DG20: #NULL! | DH20: #NULL! | DI20: #NULL! | DJ20: #NULL! | DK20: #NULL! | DL20: #NULL! | DN20: 1 | DP20: #NULL! | DQ20: #NULL! | DR20: #NULL! | DT20: #NULL! | DU20: #NULL! | DV20: #NULL! | DW20: 2 | DX20: 2 | DZ20: #NULL! | EA20: #NULL! | EI20: #NULL! | EJ20: #NULL! | EK20: #NULL! | EL20: #NULL! | EM20: 4 | EN20: 3 | EP20: 1 | EQ20: 3 | ER20: 1 | ES20: 78741 | ET20: 2 | EU20: 4 | EV20: 3 | EW20: 4 | EX20: 2 | EY20: Betty | EZ20: Escalona | FB20: Elizabeth.escalona.26@gmail.com | FC20: 5125219258 | FD20: #NULL! | FE20: #NULL! | FF20: 2 | FH20: 09 Sep 2025 - 08:55:00 CDT | FI20: 10771
A21: 120 | B21: 1 | C21: 2 | D21: 1 | E21: #NULL! | F21: 2 | G21: 2 | H21: 2 | J21: 1 | K21: 3 | P21: #NULL! | Q21: #NULL! | R21: #NULL! | S21: #NULL! | T21: 4 | U21: 3 | V21: 5 | W21: 5 | Y21: #NULL! | Z21: #NULL! | AA21: #NULL! | AB21: #NULL! | AD21: #NULL! | AE21: #NULL! | AF21: #NULL! | AG21: #NULL! | AH21: That's how I feel call went | AI21: 7 | AJ21: #NULL! | AK21: #NULL! | AL21: #NULL! | AN21: #NULL! | AO21: #NULL! | AP21: #NULL! | AQ21: #NULL! | AS21: #NULL! | AT21: #NULL! | AU21: #NULL! | AV21: #NULL! | AX21: #NULL! | AY21: #NULL! | AZ21: #NULL! | BA21: #NULL! | BC21: #NULL! | BD21: #NULL! | BE21: #NULL! | BF21: #NULL! | BH21: #NULL! | BI21: #NULL! | BJ21: #NULL! | BK21: #NULL! | BL21: 2 | BM21: 9 | BN21: Different pay stations | BO21: 99 | BP21: #NULL! | BQ21: #NULL! | BR21: #NULL! | BS21: 10 | BT21: Ways to help pay bills | BU21: 2 | BV21: #NULL! | BW21: #NULL! | BX21: #NULL! | BZ21: #NULL! | CA21: #NULL! | CB21: #NULL! | CC21: 2 | CD21: #NULL! | CE21: 2 | CF21: #NULL! | CG21: #NULL! | CI21: #NULL! | CJ21: #NULL! | CK21: #NULL! | CL21: #NULL! | CN21: #NULL! | CO21: #NULL! | CP21: #NULL! | CQ21: 2 | CR21: #NULL! | CS21: 3 | CT21: 5 | CU21: 4 | CV21: 1 | CW21: 10 | CX21: 4 | CY21: 7 | CZ21: Not seem like you're rushed off the phone | DA21: 5 | DB21: #NULL! | DC21: 7 | DD21: 0 | DE21: 0 | DF21: 0 | DG21: 0 | DH21: 0 | DI21: 0 | DJ21: 1 | DK21: 0 | DL21: 0 | DN21: 1 | DP21: #NULL! | DQ21: #NULL! | DR21: #NULL! | DT21: #NULL! | DU21: #NULL! | DV21: #NULL! | DW21: 5 | DX21: 2 | DZ21: #NULL! | EA21: #NULL! | EI21: #NULL! | EJ21: #NULL! | EK21: #NULL! | EL21: #NULL! | EM21: 9 | EN21: 2 | EP21: 5 | EQ21: 2 | ER21: 1 | ES21: 78744 | ET21: 2 | EU21: 1 | EV21: 1 | EW21: 5 | EX21: 2 | EY21: Rosie | EZ21: Taylor | FB21: essietaylor2505@gmail.com | FC21: 5129457080 | FD21: #NULL! | FE21: #NULL! | FF21: 2 | FH21: 09 Sep 2025 - 08:57:03 CDT | FI21: 9517
A22: 129 | B22: 1 | C22: 2 | D22: 1 | E22: #NULL! | F22: 2 | G22: 2 | H22: 2 | J22: 1 | K22: 4 | P22: #NULL! | Q22: #NULL! | R22: #NULL! | S22: #NULL! | T22: 10 | U22: 10 | V22: 10 | W22: 10 | Y22: #NULL! | Z22: #NULL! | AA22: #NULL! | AB22: #NULL! | AC22: Prompt efficient service | AD22: 21 | AE22: #NULL! | AF22: #NULL! | AG22: #NULL! | AI22: #NULL! | AJ22: #NULL! | AK22: #NULL! | AL22: #NULL! | AM22: Rep was helpful and knowledgeable about putting the account back into the property owner’s name | AN22: 25 | AO22: #NULL! | AP22: #NULL! | AQ22: #NULL! | AS22: #NULL! | AT22: #NULL! | AU22: #NULL! | AV22: #NULL! | AW22: Easy | AX22: 27 | AY22: #NULL! | AZ22: #NULL! | BA22: #NULL! | BC22: #NULL! | BD22: #NULL! | BE22: #NULL! | BF22: #NULL! | BG22: Stated time was more than actual. Very quick | BH22: 21 | BI22: #NULL! | BJ22: #NULL! | BK22: #NULL! | BL22: 2 | BM22: 3 | BN22: Don't recall | BO22: 98 | BP22: #NULL! | BQ22: #NULL! | BR22: #NULL! | BS22: 9 | BT22: Hours of service, required materials so callers are prepared, interesting facts/upcoming activities for Austin energy, things you can accomplish online | BU22: 12 | BV22: 22 | BW22: 2 | BX22: #NULL! | BZ22: #NULL! | CA22: #NULL! | CB22: #NULL! | CC22: 2 | CD22: #NULL! | CE22: 2 | CF22: #NULL! | CG22: #NULL! | CI22: #NULL! | CJ22: #NULL! | CK22: #NULL! | CL22: #NULL! | CN22: #NULL! | CO22: #NULL! | CP22: #NULL! | CQ22: 2 | CR22: #NULL! | CS22: 10 | CT22: 10 | CU22: 10 | CV22: 10 | CW22: 10 | CX22: 10 | CY22: 10 | DA22: #NULL! | DB22: #NULL! | DC22: 10 | DD22: #NULL! | DE22: #NULL! | DF22: #NULL! | DG22: #NULL! | DH22: #NULL! | DI22: #NULL! | DJ22: #NULL! | DK22: #NULL! | DL22: #NULL! | DN22: 1 | DP22: #NULL! | DQ22: #NULL! | DR22: #NULL! | DT22: #NULL! | DU22: #NULL! | DV22: #NULL! | DW22: 2 | DX22: 2 | DZ22: #NULL! | EA22: #NULL! | EI22: #NULL! | EJ22: #NULL! | EK22: #NULL! | EL22: #NULL! | EM22: 8 | EN22: 1 | EP22: 2 | EQ22: 2 | ER22: 2 | ES22: 78757 | ET22: 1 | EU22: 4 | EV22: 5 | EW22: 5 | EX22: 2 | EY22: Evelyn | EZ22: Brandley | FB22: Evelyncamille@yahoo.com | FC22: 5123507281 | FD22: #NULL! | FE22: #NULL! | FF22: 2 | FH22: 09 Sep 2025 - 10:14:54 CDT | FI22: 4558
A23: 135 | B23: 1 | C23: 2 | D23: 1 | E23: #NULL! | F23: 2 | G23: 2 | H23: 3 | J23: 1 | K23: 2 | P23: #NULL! | Q23: #NULL! | R23: #NULL! | S23: #NULL! | T23: 8 | U23: 9 | V23: 9 | W23: 7 | Y23: #NULL! | Z23: #NULL! | AA23: #NULL! | AB23: #NULL! | AC23: I got information that was necessary to apply for adjustment to my wastewater billing. | AD23: 26 | AE23: #NULL! | AF23: #NULL! | AG23: #NULL! | AI23: #NULL! | AJ23: #NULL! | AK23: #NULL! | AL23: #NULL! | AM23: Same as above | AN23: 26 | AO23: #NULL! | AP23: #NULL! | AQ23: #NULL! | AS23: #NULL! | AT23: #NULL! | AU23: #NULL! | AV23: #NULL! | AW23: I like speaking with a person. | AX23: 3 | AY23: #NULL! | AZ23: #NULL! | BA23: #NULL! | BC23: #NULL! | BD23: #NULL! | BE23: #NULL! | BF23: #NULL! | BH23: #NULL! | BI23: #NULL! | BJ23: #NULL! | BK23: #NULL! | BL23: 4 | BM23: #NULL! | BO23: #NULL! | BP23: #NULL! | BQ23: #NULL! | BR23: #NULL! | BS23: #NULL! | BU23: #NULL! | BV23: #NULL! | BW23: #NULL! | BX23: 10 | BZ23: #NULL! | CA23: #NULL! | CB23: #NULL! | CC23: 3 | CD23: #NULL! | CE23: 3 | CF23: #NULL! | CG23: #NULL! | CI23: #NULL! | CJ23: #NULL! | CK23: #NULL! | CL23: #NULL! | CN23: #NULL! | CO23: #NULL! | CP23: #NULL! | CQ23: 2 | CR23: #NULL! | CS23: 9 | CT23: 10 | CU23: 9 | CV23: 9 | CW23: 10 | CX23: 10 | CY23: 10 | DA23: #NULL! | DB23: #NULL! | DC23: 9 | DD23: #NULL! | DE23: #NULL! | DF23: #NULL! | DG23: #NULL! | DH23: #NULL! | DI23: #NULL! | DJ23: #NULL! | DK23: #NULL! | DL23: #NULL! | DN23: 1 | DP23: #NULL! | DQ23: #NULL! | DR23: #NULL! | DT23: #NULL! | DU23: #NULL! | DV23: #NULL! | DW23: 2 | DX23: 2 | DZ23: #NULL! | EA23: #NULL! | EI23: #NULL! | EJ23: #NULL! | EK23: #NULL! | EL23: #NULL! | EM23: 10 | EN23: 1 | EP23: 5 | EQ23: 1 | ER23: 2 | ES23: 78730 | ET23: 2 | EU23: 4 | EV23: 6 | EW23: 4 | EX23: 2 | EY23: Holly | EZ23: Hargis | FB23: hollyhargis2@gmail.com | FC23: 7132482819 | FD23: #NULL! | FE23: #NULL! | FF23: 2 | FH23: 09 Sep 2025 - 10:59:02 CDT | FI23: 4604
A24: 136 | B24: 1 | C24: 2 | D24: 1 | E24: #NULL! | F24: 3 | G24: 2 | H24: 1 | J24: 2 | K24: 20 | N24: My trashcan wasn't completely emptied. | O24: There was a trash bag left at the bottom of my trash bin after trash pickup. They only emptied half of the bin. | P24: 12 | Q24: #NULL! | R24: #NULL! | S24: #NULL! | T24: 3 | U24: 3 | V24: 3 | W24: 10 | X24: It takes too long to speak to someone. | Y24: 2 | Z24: #NULL! | AA24: #NULL! | AB24: #NULL! | AD24: #NULL! | AE24: #NULL! | AF24: #NULL! | AG24: #NULL! | AH24: What I speak, it never understands me correctly, no matter how slow and clear I speak. | AI24: 9 | AJ24: #NULL! | AK24: #NULL! | AL24: #NULL! | AN24: #NULL! | AO24: #NULL! | AP24: #NULL! | AQ24: #NULL! | AR24: I would much rather speak to a human being. | AS24: 3 | AT24: #NULL! | AU24: #NULL! | AV24: #NULL! | AX24: #NULL! | AY24: #NULL! | AZ24: #NULL! | BA24: #NULL! | BC24: #NULL! | BD24: #NULL! | BE24: #NULL! | BF24: #NULL! | BG24: I rarely ever have to wait very long. | BH24: 21 | BI24: #NULL! | BJ24: #NULL! | BK24: #NULL! | BL24: 2 | BM24: 4 | BN24: I don't know | BO24: 98 | BP24: #NULL! | BQ24: #NULL! | BR24: #NULL! | BS24: 10 | BT24: It would be nice to know what benefits the city offers for free and what rebates are available. | BU24: 1 | BV24: #NULL! | BW24: #NULL! | BX24: #NULL! | BZ24: #NULL! | CA24: #NULL! | CB24: #NULL! | CC24: 1 | CD24: 9 | CE24: 2 | CF24: #NULL! | CG24: #NULL! | CI24: #NULL! | CJ24: #NULL! | CK24: #NULL! | CL24: #NULL! | CN24: #NULL! | CO24: #NULL! | CP24: #NULL! | CQ24: 2 | CR24: #NULL! | CS24: 10 | CT24: 9 | CU24: 10 | CV24: 11 | CW24: 10 | CX24: 10 | CY24: 10 | DA24: #NULL! | DB24: #NULL! | DC24: 10 | DD24: #NULL! | DE24: #NULL! | DF24: #NULL! | DG24: #NULL! | DH24: #NULL! | DI24: #NULL! | DJ24: #NULL! | DK24: #NULL! | DL24: #NULL! | DN24: 1 | DP24: #NULL! | DQ24: #NULL! | DR24: #NULL! | DT24: #NULL! | DU24: #NULL! | DV24: #NULL! | DW24: 4 | DX24: 3 | DZ24: #NULL! | EA24: #NULL! | EI24: #NULL! | EJ24: #NULL! | EK24: #NULL! | EL24: #NULL! | EM24: 8 | EN24: 3 | EP24: 1 | EQ24: 2 | ER24: 2 | ES24: 78747 | ET24: 1 | EU24: 4 | EV24: 4 | EW24: 5 | EX24: 2 | EY24: Angelina | EZ24: Gonzalez | FB24: Gonzalezangela31@gmail.com | FC24: 5128675309 | FD24: #NULL! | FE24: #NULL! | FF24: 2 | FH24: 09 Sep 2025 - 11:08:18 CDT | FI24: 2087
A25: 142 | B25: 1 | C25: 2 | D25: 1 | E25: #NULL! | F25: 2 | G25: 2 | H25: 2 | J25: 1 | K25: 11 | P25: #NULL! | Q25: #NULL! | R25: #NULL! | S25: #NULL! | T25: 10 | U25: 10 | V25: 10 | W25: 10 | Y25: #NULL! | Z25: #NULL! | AA25: #NULL! | AB25: #NULL! | AC25: Short waiting time | AD25: 21 | AE25: #NULL! | AF25: #NULL! | AG25: #NULL! | AI25: #NULL! | AJ25: #NULL! | AK25: #NULL! | AL25: #NULL! | AM25: All necessary info provided | AN25: 30 | AO25: #NULL! | AP25: #NULL! | AQ25: #NULL! | AS25: #NULL! | AT25: #NULL! | AU25: #NULL! | AV25: #NULL! | AW25: Excellent | AX25: 28 | AY25: #NULL! | AZ25: #NULL! | BA25: #NULL! | BC25: #NULL! | BD25: #NULL! | BE25: #NULL! | BF25: #NULL! | BG25: Excellent | BH25: 28 | BI25: #NULL! | BJ25: #NULL! | BK25: #NULL! | BL25: 2 | BM25: 5 | BN25: Recording about how long for wait time. What department to call for making payments? | BO25: 8 | BP25: #NULL! | BQ25: #NULL! | BR25: #NULL! | BS25: 10 | BT25: None | BU25: 97 | BV25: #NULL! | BW25: #NULL! | BX25: #NULL! | BZ25: #NULL! | CA25: #NULL! | CB25: #NULL! | CC25: 2 | CD25: #NULL! | CE25: 2 | CF25: #NULL! | CG25: #NULL! | CI25: #NULL! | CJ25: #NULL! | CK25: #NULL! | CL25: #NULL! | CN25: #NULL! | CO25: #NULL! | CP25: #NULL! | CQ25: 2 | CR25: #NULL! | CS25: 10 | CT25: 10 | CU25: 10 | CV25: 10 | CW25: 10 | CX25: 10 | CY25: 10 | DA25: #NULL! | DB25: #NULL! | DC25: 10 | DD25: #NULL! | DE25: #NULL! | DF25: #NULL! | DG25: #NULL! | DH25: #NULL! | DI25: #NULL! | DJ25: #NULL! | DK25: #NULL! | DL25: #NULL! | DN25: 1 | DP25: #NULL! | DQ25: #NULL! | DR25: #NULL! | DT25: #NULL! | DU25: #NULL! | DV25: #NULL! | DW25: 3 | DX25: 2 | DZ25: #NULL! | EA25: #NULL! | EI25: #NULL! | EJ25: #NULL! | EK25: #NULL! | EL25: #NULL! | EM25: 10 | EN25: 2 | EP25: 5 | EQ25: 1 | ER25: 2 | ES25: 78752 | ET25: 2 | EU25: 3 | EV25: 3 | EW25: 5 | EX25: 2 | EY25: Darleen | EZ25: Gilmore | FB25: darleen1947@gmail.com | FC25: 5129255896 | FD25: #NULL! | FE25: #NULL! | FF25: 2 | FH25: 09 Sep 2025 - 11:56:29 CDT | FI25: 3261
A26: 147 | B26: 1 | C26: 2 | D26: 1 | E26: #NULL! | F26: 2 | G26: 2 | H26: 2 | J26: 1 | K26: 38 | N26: Inquiry about bill assistance program | P26: #NULL! | Q26: #NULL! | R26: #NULL! | S26: #NULL! | T26: 10 | U26: 10 | V26: 10 | W26: 10 | Y26: #NULL! | Z26: #NULL! | AA26: #NULL! | AB26: #NULL! | AC26: I got all the information I needed in a timely fashion. | AD26: 21 | AE26: #NULL! | AF26: #NULL! | AG26: #NULL! | AI26: #NULL! | AJ26: #NULL! | AK26: #NULL! | AL26: #NULL! | AM26: I got all the information I needed in a timely fashion. | AN26: 21 | AO26: #NULL! | AP26: #NULL! | AQ26: #NULL! | AS26: #NULL! | AT26: #NULL! | AU26: #NULL! | AV26: #NULL! | AW26: I got all the information I needed in a timely fashion from a polite associate. | AX26: 21 | AY26: #NULL! | AZ26: #NULL! | BA26: #NULL! | BC26: #NULL! | BD26: #NULL! | BE26: #NULL! | BF26: #NULL! | BG26: I got all the information I needed in a timely fashion. | BH26: 21 | BI26: #NULL! | BJ26: #NULL! | BK26: #NULL! | BL26: 2 | BM26: 10 | BN26: I don't remember the info I heard while on hold. | BO26: 98 | BP26: #NULL! | BQ26: #NULL! | BR26: #NULL! | BS26: 8 | BT26: N/a | BU26: 97 | BV26: #NULL! | BW26: #NULL! | BX26: #NULL! | BZ26: #NULL! | CA26: #NULL! | CB26: #NULL! | CC26: 2 | CD26: #NULL! | CE26: 2 | CF26: #NULL! | CG26: #NULL! | CI26: #NULL! | CJ26: #NULL! | CK26: #NULL! | CL26: #NULL! | CN26: #NULL! | CO26: #NULL! | CP26: #NULL! | CQ26: 2 | CR26: #NULL! | CS26: 10 | CT26: 10 | CU26: 10 | CV26: 10 | CW26: 10 | CX26: 10 | CY26: 10 | DA26: #NULL! | DB26: #NULL! | DC26: 10 | DD26: #NULL! | DE26: #NULL! | DF26: #NULL! | DG26: #NULL! | DH26: #NULL! | DI26: #NULL! | DJ26: #NULL! | DK26: #NULL! | DL26: #NULL! | DN26: 1 | DP26: #NULL! | DQ26: #NULL! | DR26: #NULL! | DT26: #NULL! | DU26: #NULL! | DV26: #NULL! | DW26: 2 | DX26: 2 | DZ26: #NULL! | EA26: #NULL! | EI26: #NULL! | EJ26: #NULL! | EK26: #NULL! | EL26: #NULL! | EM26: 4 | EN26: 7 | EP26: 3 | EQ26: 2 | ER26: 2 | ES26: 78753 | ET26: 2 | EU26: 3 | EV26: 3 | EW26: 5 | EX26: 1 | EY26: Douglas | EZ26: Bass | FB26: Dj_182@YAHOO.COM | FC26: 9094479283 | FD26: #NULL! | FE26: #NULL! | FF26: 1 | FH26: 09 Sep 2025 - 12:05:13 CDT | FI26: 6372
